2023-10-19 00:11:16.709 | DEBUG    | __main__:main:51 - Программа инициализирована
2023-10-19 00:11:19.021 | INFO     | __main__:main:59 - Пользователь ввёл данные name = Тест
2023-10-19 00:11:19.547 | INFO     | __main__:main:63 - Пользователь ввёл данные length = 1.0
2023-10-19 00:11:19.914 | INFO     | __main__:main:65 - Пользователь ввёл данные width = 2.0
2023-10-19 00:11:20.304 | INFO     | __main__:main:67 - Пользователь ввёл данные height = 3.0
2023-10-19 00:11:20.304 | SUCCESS  | __main__:calculate_wall_area:13 - Площадь стен посчитана
2023-10-19 00:11:20.304 | SUCCESS  | __main__:calculate_ceiling_area:17 - Площадь потолка посчитана
2023-10-19 00:11:20.304 | SUCCESS  | __main__:calculate_floor_area:21 - Площадь пола посчитана
2023-10-19 00:11:20.305 | SUCCESS  | __main__:add_room:37 - Комната добавлена
2023-10-19 00:11:26.716 | INFO     | __main__:main:59 - Пользователь ввёл данные name = Тест 2
2023-10-19 00:11:28.214 | INFO     | __main__:main:63 - Пользователь ввёл данные length = 4.0
2023-10-19 00:11:28.577 | INFO     | __main__:main:65 - Пользователь ввёл данные width = 5.0
2023-10-19 00:11:29.063 | INFO     | __main__:main:67 - Пользователь ввёл данные height = 6.0
2023-10-19 00:11:29.064 | SUCCESS  | __main__:calculate_wall_area:13 - Площадь стен посчитана
2023-10-19 00:11:29.064 | SUCCESS  | __main__:calculate_ceiling_area:17 - Площадь потолка посчитана
2023-10-19 00:11:29.064 | SUCCESS  | __main__:calculate_floor_area:21 - Площадь пола посчитана
2023-10-19 00:11:29.064 | SUCCESS  | __main__:add_room:37 - Комната добавлена
2023-10-19 00:11:33.029 | INFO     | __main__:main:76 - Пользователь ввёл данные wall_cost = 7.0
2023-10-19 00:11:33.392 | INFO     | __main__:main:78 - Пользователь ввёл данные ceiling_cost = 8.0
2023-10-19 00:11:33.955 | INFO     | __main__:main:80 - Пользователь ввёл данные floor_cost = 9.0
2023-10-19 00:11:33.955 | SUCCESS  | __main__:calculate_total_cost:44 - Результат посчитан total_cost = 227.125
2023-10-19 00:11:33.956 | INFO     | __main__:main:85 - Открыт файл results.csv
2023-10-19 00:11:33.957 | SUCCESS  | __main__:calculate_wall_area:13 - Площадь стен посчитана
2023-10-19 00:11:33.957 | SUCCESS  | __main__:calculate_floor_area:21 - Площадь пола посчитана
2023-10-19 00:11:33.957 | SUCCESS  | __main__:calculate_ceiling_area:17 - Площадь потолка посчитана
2023-10-19 00:11:33.957 | SUCCESS  | __main__:calculate_wall_area:13 - Площадь стен посчитана
2023-10-19 00:11:33.957 | SUCCESS  | __main__:calculate_floor_area:21 - Площадь пола посчитана
2023-10-19 00:11:33.957 | SUCCESS  | __main__:calculate_ceiling_area:17 - Площадь потолка посчитана
2023-10-19 00:11:33.957 | SUCCESS  | __main__:<module>:102 - Расчёт стоимости окончен. Программа завершена.
2025-07-14 16:51:49.318 | DEBUG    | __main__:main:51 - Программа инициализирована
2025-07-14 17:01:13.727 | DEBUG    | __main__:main:71 - Программа инициализирована
2025-07-14 17:01:13.728 | ERROR    | __main__:<module>:140 - An error has been caught in function '<module>', process 'MainProcess' (8552), thread 'MainThread' (19688):
Traceback (most recent call last):

> File "C:\Users\Artem\OneDrive\Рабочий стол\Bug_3\main.py", line 140, in <module>
    good = main()
           └ <function main at 0x000001A9EFAE65C0>

  File "C:\Users\Artem\OneDrive\Рабочий стол\Bug_3\main.py", line 73, in main
    apartment = Apartment()
                └ <class '__main__.Apartment'>

  File "C:\Users\Artem\OneDrive\Рабочий стол\Bug_3\main.py", line 43, in __init__
    self.rooms = []
    │    └ []
    └ Apartment(rooms=[])

  File "C:\Users\Artem\OneDrive\Рабочий стол\Bug_3\.venv\Lib\site-packages\pydantic\main.py", line 998, in __setattr__
    setattr_handler(self, name, value)  # call here to not memo on possibly unknown fields
    │               │     │     └ []
    │               │     └ 'rooms'
    │               └ Apartment(rooms=[])
    └ <function _model_field_setattr_handler at 0x000001A9EF79C2C0>
  File "C:\Users\Artem\OneDrive\Рабочий стол\Bug_3\.venv\Lib\site-packages\pydantic\main.py", line 99, in _model_field_setattr_handler
    model.__pydantic_fields_set__.add(name)
    │     │                           └ 'rooms'
    │     └ <member '__pydantic_fields_set__' of 'BaseModel' objects>
    └ Apartment(rooms=[])
  File "C:\Users\Artem\OneDrive\Рабочий стол\Bug_3\.venv\Lib\site-packages\pydantic\main.py", line 988, in __getattr__
    return super().__getattribute__(item)  # Raises AttributeError if appropriate
                                    └ '__pydantic_fields_set__'

AttributeError: 'Apartment' object has no attribute '__pydantic_fields_set__'. Did you mean: '__pydantic_fields__'?
2025-07-14 17:01:13.733 | CRITICAL | __main__:<module>:144 - Что-то произошло в процессе работы программы.
2025-07-14 17:01:19.779 | DEBUG    | __main__:main:71 - Программа инициализирована
2025-07-14 17:01:19.779 | ERROR    | __main__:<module>:140 - An error has been caught in function '<module>', process 'MainProcess' (5984), thread 'MainThread' (2984):
Traceback (most recent call last):

> File "C:\Users\Artem\OneDrive\Рабочий стол\Bug_3\main.py", line 140, in <module>
    good = main()
           └ <function main at 0x00000215194A7F60>

  File "C:\Users\Artem\OneDrive\Рабочий стол\Bug_3\main.py", line 73, in main
    apartment = Apartment()
                └ <class '__main__.Apartment'>

  File "C:\Users\Artem\OneDrive\Рабочий стол\Bug_3\main.py", line 43, in __init__
    self.rooms = []
    │    └ []
    └ Apartment(rooms=[])

  File "C:\Users\Artem\OneDrive\Рабочий стол\Bug_3\.venv\Lib\site-packages\pydantic\main.py", line 998, in __setattr__
    setattr_handler(self, name, value)  # call here to not memo on possibly unknown fields
    │               │     │     └ []
    │               │     └ 'rooms'
    │               └ Apartment(rooms=[])
    └ <function _model_field_setattr_handler at 0x000002151923A200>
  File "C:\Users\Artem\OneDrive\Рабочий стол\Bug_3\.venv\Lib\site-packages\pydantic\main.py", line 99, in _model_field_setattr_handler
    model.__pydantic_fields_set__.add(name)
    │     │                           └ 'rooms'
    │     └ <member '__pydantic_fields_set__' of 'BaseModel' objects>
    └ Apartment(rooms=[])
  File "C:\Users\Artem\OneDrive\Рабочий стол\Bug_3\.venv\Lib\site-packages\pydantic\main.py", line 988, in __getattr__
    return super().__getattribute__(item)  # Raises AttributeError if appropriate
                                    └ '__pydantic_fields_set__'

AttributeError: 'Apartment' object has no attribute '__pydantic_fields_set__'. Did you mean: '__pydantic_fields__'?
2025-07-14 17:01:19.783 | CRITICAL | __main__:<module>:144 - Что-то произошло в процессе работы программы.
2025-07-14 17:02:32.067 | DEBUG    | __main__:main:71 - Программа инициализирована
2025-07-14 17:02:32.068 | ERROR    | __main__:<module>:140 - An error has been caught in function '<module>', process 'MainProcess' (20592), thread 'MainThread' (21948):
Traceback (most recent call last):

> File "C:\Users\Artem\OneDrive\Рабочий стол\Bug_3\main.py", line 140, in <module>
    good = main()
           └ <function main at 0x00000219A9197F60>

  File "C:\Users\Artem\OneDrive\Рабочий стол\Bug_3\main.py", line 73, in main
    apartment = Apartment()
                └ <class '__main__.Apartment'>

  File "C:\Users\Artem\OneDrive\Рабочий стол\Bug_3\main.py", line 43, in __init__
    self.rooms = list()
    │    └ []
    └ Apartment(rooms=[])

  File "C:\Users\Artem\OneDrive\Рабочий стол\Bug_3\.venv\Lib\site-packages\pydantic\main.py", line 998, in __setattr__
    setattr_handler(self, name, value)  # call here to not memo on possibly unknown fields
    │               │     │     └ []
    │               │     └ 'rooms'
    │               └ Apartment(rooms=[])
    └ <function _model_field_setattr_handler at 0x00000219A8F4A200>
  File "C:\Users\Artem\OneDrive\Рабочий стол\Bug_3\.venv\Lib\site-packages\pydantic\main.py", line 99, in _model_field_setattr_handler
    model.__pydantic_fields_set__.add(name)
    │     │                           └ 'rooms'
    │     └ <member '__pydantic_fields_set__' of 'BaseModel' objects>
    └ Apartment(rooms=[])
  File "C:\Users\Artem\OneDrive\Рабочий стол\Bug_3\.venv\Lib\site-packages\pydantic\main.py", line 988, in __getattr__
    return super().__getattribute__(item)  # Raises AttributeError if appropriate
                                    └ '__pydantic_fields_set__'

AttributeError: 'Apartment' object has no attribute '__pydantic_fields_set__'. Did you mean: '__pydantic_fields__'?
2025-07-14 17:02:32.071 | CRITICAL | __main__:<module>:144 - Что-то произошло в процессе работы программы.
2025-07-14 17:08:23.757 | DEBUG    | __main__:main:76 - Программа инициализирована
2025-07-14 17:09:45.195 | DEBUG    | __main__:main:76 - Программа инициализирована
2025-07-14 17:09:49.339 | INFO     | __main__:main:84 - Пользователь ввёл данные name = test 1
2025-07-14 17:09:51.724 | INFO     | __main__:main:88 - Пользователь ввёл данные length = 5.0
2025-07-14 17:09:53.044 | INFO     | __main__:main:90 - Пользователь ввёл данные width = 5.0
2025-07-14 17:09:55.289 | INFO     | __main__:main:92 - Пользователь ввёл данные height = 3.0
2025-07-14 17:09:55.290 | SUCCESS  | __main__:calculate_wall_area:27 - Площадь стен посчитана
2025-07-14 17:09:55.290 | SUCCESS  | __main__:calculate_ceiling_area:31 - Площадь потолка посчитана
2025-07-14 17:09:55.290 | SUCCESS  | __main__:calculate_floor_area:35 - Площадь пола посчитана
2025-07-14 17:09:55.290 | SUCCESS  | __main__:add_room:58 - Комната добавлена
2025-07-14 17:10:06.760 | INFO     | __main__:main:101 - Пользователь ввёл данные wall_cost = 50.0
2025-07-14 17:10:12.656 | INFO     | __main__:main:105 - Пользователь ввёл данные ceiling_cost = 100.0
2025-07-14 17:10:16.309 | INFO     | __main__:main:107 - Пользователь ввёл данные floor_cost = 60.0
2025-07-14 17:10:16.310 | SUCCESS  | __main__:calculate_total_cost:68 - Результат посчитан total_cost = 0.25
2025-07-14 17:10:16.311 | INFO     | __main__:main:112 - Открыт файл results.csv
2025-07-14 17:10:16.311 | ERROR    | __main__:<module>:145 - An error has been caught in function '<module>', process 'MainProcess' (16852), thread 'MainThread' (10884):
Traceback (most recent call last):

> File "C:\Users\Artem\OneDrive\Рабочий стол\Bug_3\main.py", line 145, in <module>
    good = main()
           └ <function main at 0x0000026E878C0040>

  File "C:\Users\Artem\OneDrive\Рабочий стол\Bug_3\main.py", line 114, in main
    writer.writerow(["Комната", "Площадь стен", "Площадь потолка", "Площадь пола"])
    │      └ <method 'writerow' of '_csv.writer' objects>
    └ <_csv.writer object at 0x0000026E87891A20>

  File "C:\Users\Artem\AppData\Roaming\uv\python\cpython-3.13.5-windows-x86_64-none\Lib\encodings\cp1252.py", line 19, in encode
    return codecs.charmap_encode(input,self.errors,encoding_table)[0]
           │      │              │     │    │      └ <EncodingMap object at 0x0000026E84A2CA80>
           │      │              │     │    └ 'strict'
           │      │              │     └ <encodings.cp1252.IncrementalEncoder object at 0x0000026E8748C6E0>
           │      │              └ 'Комната;Площадь стен;Площадь потолка;Площадь пола\r\n'
           │      └ <built-in function charmap_encode>
           └ <module 'codecs' (frozen)>

UnicodeEncodeError: 'charmap' codec can't encode characters in position 0-6: character maps to <undefined>
2025-07-14 17:10:16.382 | CRITICAL | __main__:<module>:149 - Что-то произошло в процессе работы программы.
2025-07-14 17:14:39.407 | DEBUG    | __main__:main:76 - Программа инициализирована
2025-07-14 17:14:48.666 | INFO     | __main__:main:84 - Пользователь ввёл данные name = test 1
2025-07-14 17:14:49.706 | INFO     | __main__:main:88 - Пользователь ввёл данные length = 5.0
2025-07-14 17:14:50.203 | INFO     | __main__:main:90 - Пользователь ввёл данные width = 5.0
2025-07-14 17:14:51.041 | INFO     | __main__:main:92 - Пользователь ввёл данные height = 3.0
2025-07-14 17:14:51.048 | SUCCESS  | __main__:calculate_wall_area:27 - Площадь стен посчитана
2025-07-14 17:14:51.048 | SUCCESS  | __main__:calculate_ceiling_area:31 - Площадь потолка посчитана
2025-07-14 17:14:51.049 | SUCCESS  | __main__:calculate_floor_area:35 - Площадь пола посчитана
2025-07-14 17:14:51.049 | SUCCESS  | __main__:add_room:58 - Комната добавлена
2025-07-14 17:14:55.360 | INFO     | __main__:main:101 - Пользователь ввёл данные wall_cost = 50.0
2025-07-14 17:14:56.224 | INFO     | __main__:main:105 - Пользователь ввёл данные ceiling_cost = 100.0
2025-07-14 17:14:57.074 | INFO     | __main__:main:107 - Пользователь ввёл данные floor_cost = 60.0
2025-07-14 17:14:57.076 | SUCCESS  | __main__:calculate_total_cost:68 - Результат посчитан total_cost = 0.25
2025-07-14 17:14:57.077 | INFO     | __main__:main:112 - Открыт файл results.csv
2025-07-14 17:14:57.078 | SUCCESS  | __main__:calculate_wall_area:27 - Площадь стен посчитана
2025-07-14 17:14:57.079 | SUCCESS  | __main__:calculate_floor_area:35 - Площадь пола посчитана
2025-07-14 17:14:57.080 | SUCCESS  | __main__:calculate_ceiling_area:31 - Площадь потолка посчитана
2025-07-14 17:14:57.082 | ERROR    | __main__:<module>:145 - An error has been caught in function '<module>', process 'MainProcess' (13800), thread 'MainThread' (26504):
Traceback (most recent call last):

> File "C:\Users\Artem\OneDrive\Рабочий стол\Bug_3\main.py", line 145, in <module>
    good = main()
           └ <function main at 0x0000022199B00040>

  File "C:\Users\Artem\OneDrive\Рабочий стол\Bug_3\main.py", line 124, in main
    writer.writerow(
    │      └ <method 'writerow' of '_csv.writer' objects>
    └ <_csv.writer object at 0x0000022199AD1900>

  File "C:\Users\Artem\AppData\Roaming\uv\python\cpython-3.13.5-windows-x86_64-none\Lib\encodings\cp1252.py", line 19, in encode
    return codecs.charmap_encode(input,self.errors,encoding_table)[0]
           │      │              │     │    │      └ <EncodingMap object at 0x0000022196BAB670>
           │      │              │     │    └ 'strict'
           │      │              │     └ <encodings.cp1252.IncrementalEncoder object at 0x000002219970C6E0>
           │      │              └ 'Итого;30.0;25.0;-25.0\r\n'
           │      └ <built-in function charmap_encode>
           └ <module 'codecs' (frozen)>

UnicodeEncodeError: 'charmap' codec can't encode characters in position 0-4: character maps to <undefined>
2025-07-14 17:14:57.086 | CRITICAL | __main__:<module>:149 - Что-то произошло в процессе работы программы.
2025-07-14 17:17:08.761 | DEBUG    | __main__:main:76 - Программа инициализирована
2025-07-14 17:17:15.136 | INFO     | __main__:main:84 - Пользователь ввёл данные name = test 1
2025-07-14 17:17:17.191 | INFO     | __main__:main:88 - Пользователь ввёл данные length = 5.0
2025-07-14 17:17:17.603 | INFO     | __main__:main:90 - Пользователь ввёл данные width = 5.0
2025-07-14 17:17:18.379 | INFO     | __main__:main:92 - Пользователь ввёл данные height = 3.0
2025-07-14 17:17:18.380 | SUCCESS  | __main__:calculate_wall_area:27 - Площадь стен посчитана
2025-07-14 17:17:18.382 | SUCCESS  | __main__:calculate_ceiling_area:31 - Площадь потолка посчитана
2025-07-14 17:17:18.382 | SUCCESS  | __main__:calculate_floor_area:35 - Площадь пола посчитана
2025-07-14 17:17:18.383 | SUCCESS  | __main__:add_room:58 - Комната добавлена
2025-07-14 17:17:22.142 | INFO     | __main__:main:101 - Пользователь ввёл данные wall_cost = 50.0
2025-07-14 17:17:23.078 | INFO     | __main__:main:105 - Пользователь ввёл данные ceiling_cost = 100.0
2025-07-14 17:17:24.227 | INFO     | __main__:main:107 - Пользователь ввёл данные floor_cost = 60.0
2025-07-14 17:17:24.227 | SUCCESS  | __main__:calculate_total_cost:68 - Результат посчитан total_cost = 0.25
2025-07-14 17:17:24.228 | INFO     | __main__:main:112 - Открыт файл results.csv
2025-07-14 17:17:24.229 | SUCCESS  | __main__:calculate_wall_area:27 - Площадь стен посчитана
2025-07-14 17:17:24.229 | SUCCESS  | __main__:calculate_ceiling_area:31 - Площадь потолка посчитана
2025-07-14 17:17:24.229 | SUCCESS  | __main__:calculate_floor_area:35 - Площадь пола посчитана
2025-07-14 17:17:24.230 | ERROR    | __main__:<module>:145 - An error has been caught in function '<module>', process 'MainProcess' (17156), thread 'MainThread' (9288):
Traceback (most recent call last):

> File "C:\Users\Artem\OneDrive\Рабочий стол\Bug_3\main.py", line 145, in <module>
    good = main()
           └ <function main at 0x00000222130400E0>

  File "C:\Users\Artem\OneDrive\Рабочий стол\Bug_3\main.py", line 124, in main
    writer.writerow(
    │      └ <method 'writerow' of '_csv.writer' objects>
    └ <_csv.writer object at 0x00000222130118A0>

  File "C:\Users\Artem\AppData\Roaming\uv\python\cpython-3.13.5-windows-x86_64-none\Lib\encodings\cp1252.py", line 19, in encode
    return codecs.charmap_encode(input,self.errors,encoding_table)[0]
           │      │              │     │    │      └ <EncodingMap object at 0x0000022210169490>
           │      │              │     │    └ 'strict'
           │      │              │     └ <encodings.cp1252.IncrementalEncoder object at 0x0000022212C4C6E0>
           │      │              └ 'Итого;30.0;25.0;-25.0\r\r\n'
           │      └ <built-in function charmap_encode>
           └ <module 'codecs' (frozen)>

UnicodeEncodeError: 'charmap' codec can't encode characters in position 0-4: character maps to <undefined>
2025-07-14 17:17:24.232 | CRITICAL | __main__:<module>:149 - Что-то произошло в процессе работы программы.
2025-07-14 17:18:05.393 | DEBUG    | __main__:main:76 - Программа инициализирована
2025-07-14 17:18:11.479 | INFO     | __main__:main:84 - Пользователь ввёл данные name = test 1
2025-07-14 17:18:13.144 | INFO     | __main__:main:88 - Пользователь ввёл данные length = 50.0
2025-07-14 17:18:14.123 | INFO     | __main__:main:90 - Пользователь ввёл данные width = 100.0
2025-07-14 17:18:15.278 | INFO     | __main__:main:92 - Пользователь ввёл данные height = 60.0
2025-07-14 17:18:15.278 | SUCCESS  | __main__:calculate_wall_area:27 - Площадь стен посчитана
2025-07-14 17:18:15.278 | SUCCESS  | __main__:calculate_ceiling_area:31 - Площадь потолка посчитана
2025-07-14 17:18:15.278 | SUCCESS  | __main__:calculate_floor_area:35 - Площадь пола посчитана
2025-07-14 17:18:15.279 | SUCCESS  | __main__:add_room:58 - Комната добавлена
2025-07-14 17:18:18.493 | INFO     | __main__:main:101 - Пользователь ввёл данные wall_cost = 5.0
2025-07-14 17:18:21.001 | INFO     | __main__:main:105 - Пользователь ввёл данные ceiling_cost = 10.0
2025-07-14 17:18:22.418 | INFO     | __main__:main:107 - Пользователь ввёл данные floor_cost = 6.0
2025-07-14 17:18:22.418 | SUCCESS  | __main__:calculate_total_cost:68 - Результат посчитан total_cost = 15500.0
2025-07-14 17:18:22.419 | INFO     | __main__:main:112 - Открыт файл results.csv
2025-07-14 17:18:22.419 | SUCCESS  | __main__:calculate_wall_area:27 - Площадь стен посчитана
2025-07-14 17:18:22.420 | SUCCESS  | __main__:calculate_ceiling_area:31 - Площадь потолка посчитана
2025-07-14 17:18:22.420 | SUCCESS  | __main__:calculate_floor_area:35 - Площадь пола посчитана
2025-07-14 17:18:22.420 | ERROR    | __main__:<module>:145 - An error has been caught in function '<module>', process 'MainProcess' (21372), thread 'MainThread' (27812):
Traceback (most recent call last):

> File "C:\Users\Artem\OneDrive\Рабочий стол\Bug_3\main.py", line 145, in <module>
    good = main()
           └ <function main at 0x0000027242AB00E0>

  File "C:\Users\Artem\OneDrive\Рабочий стол\Bug_3\main.py", line 124, in main
    writer.writerow(
    │      └ <method 'writerow' of '_csv.writer' objects>
    └ <_csv.writer object at 0x0000027242A818A0>

  File "C:\Users\Artem\AppData\Roaming\uv\python\cpython-3.13.5-windows-x86_64-none\Lib\encodings\cp1252.py", line 19, in encode
    return codecs.charmap_encode(input,self.errors,encoding_table)[0]
           │      │              │     │    │      └ <EncodingMap object at 0x000002723FC8C780>
           │      │              │     │    └ 'strict'
           │      │              │     └ <encodings.cp1252.IncrementalEncoder object at 0x00000272426BC6E0>
           │      │              └ 'Итого;9000.0;5000.0;-5000.0\r\r\n'
           │      └ <built-in function charmap_encode>
           └ <module 'codecs' (frozen)>

UnicodeEncodeError: 'charmap' codec can't encode characters in position 0-4: character maps to <undefined>
2025-07-14 17:18:22.425 | CRITICAL | __main__:<module>:149 - Что-то произошло в процессе работы программы.
2025-07-14 17:19:39.467 | DEBUG    | __main__:main:76 - Программа инициализирована
2025-07-14 17:19:43.360 | INFO     | __main__:main:84 - Пользователь ввёл данные name = test
2025-07-14 17:19:44.985 | INFO     | __main__:main:88 - Пользователь ввёл данные length = 5.0
2025-07-14 17:19:45.304 | INFO     | __main__:main:90 - Пользователь ввёл данные width = 5.0
2025-07-14 17:19:46.914 | INFO     | __main__:main:92 - Пользователь ввёл данные height = 3.0
2025-07-14 17:19:46.914 | SUCCESS  | __main__:calculate_wall_area:27 - Площадь стен посчитана
2025-07-14 17:19:46.915 | SUCCESS  | __main__:calculate_ceiling_area:31 - Площадь потолка посчитана
2025-07-14 17:19:46.915 | SUCCESS  | __main__:calculate_floor_area:35 - Площадь пола посчитана
2025-07-14 17:19:46.915 | SUCCESS  | __main__:add_room:58 - Комната добавлена
2025-07-14 17:19:49.897 | INFO     | __main__:main:101 - Пользователь ввёл данные wall_cost = 50.0
2025-07-14 17:19:50.902 | INFO     | __main__:main:105 - Пользователь ввёл данные ceiling_cost = 100.0
2025-07-14 17:19:51.924 | INFO     | __main__:main:107 - Пользователь ввёл данные floor_cost = 60.0
2025-07-14 17:19:51.924 | SUCCESS  | __main__:calculate_total_cost:68 - Результат посчитан total_cost = 0.25
2025-07-14 17:19:51.925 | INFO     | __main__:main:112 - Открыт файл results.csv
2025-07-14 17:19:51.925 | SUCCESS  | __main__:calculate_wall_area:27 - Площадь стен посчитана
2025-07-14 17:19:51.925 | SUCCESS  | __main__:calculate_ceiling_area:31 - Площадь потолка посчитана
2025-07-14 17:19:51.925 | SUCCESS  | __main__:calculate_floor_area:35 - Площадь пола посчитана
2025-07-14 17:19:51.926 | SUCCESS  | __main__:<module>:147 - Расчёт стоимости окончен. Программа завершена.
2025-07-14 17:23:20.745 | DEBUG    | __main__:main:76 - Программа инициализирована
2025-07-14 17:23:23.465 | INFO     | __main__:main:84 - Пользователь ввёл данные name = test
2025-07-14 17:23:25.250 | INFO     | __main__:main:88 - Пользователь ввёл данные length = 5.0
2025-07-14 17:23:25.624 | INFO     | __main__:main:90 - Пользователь ввёл данные width = 5.0
2025-07-14 17:23:26.678 | INFO     | __main__:main:92 - Пользователь ввёл данные height = 3.0
2025-07-14 17:23:26.679 | SUCCESS  | __main__:calculate_wall_area:27 - Площадь стен посчитана
2025-07-14 17:23:26.679 | SUCCESS  | __main__:calculate_ceiling_area:31 - Площадь потолка посчитана
2025-07-14 17:23:26.679 | SUCCESS  | __main__:calculate_floor_area:35 - Площадь пола посчитана
2025-07-14 17:23:26.679 | SUCCESS  | __main__:add_room:58 - Комната добавлена
2025-07-14 17:23:29.439 | INFO     | __main__:main:101 - Пользователь ввёл данные wall_cost = 50.0
2025-07-14 17:23:30.471 | INFO     | __main__:main:105 - Пользователь ввёл данные ceiling_cost = 100.0
2025-07-14 17:23:31.525 | INFO     | __main__:main:107 - Пользователь ввёл данные floor_cost = 70.0
2025-07-14 17:23:31.525 | SUCCESS  | __main__:calculate_total_cost:68 - Результат посчитан total_cost = 2250.0
2025-07-14 17:23:31.526 | INFO     | __main__:main:112 - Открыт файл results.csv
2025-07-14 17:23:31.527 | SUCCESS  | __main__:calculate_wall_area:27 - Площадь стен посчитана
2025-07-14 17:23:31.527 | SUCCESS  | __main__:calculate_ceiling_area:31 - Площадь потолка посчитана
2025-07-14 17:23:31.528 | SUCCESS  | __main__:calculate_floor_area:35 - Площадь пола посчитана
2025-07-14 17:23:31.528 | SUCCESS  | __main__:<module>:147 - Расчёт стоимости окончен. Программа завершена.
2025-07-14 17:24:48.045 | DEBUG    | __main__:main:76 - Программа инициализирована
2025-07-14 17:25:00.723 | INFO     | __main__:main:84 - Пользователь ввёл данные name = test
2025-07-14 17:25:02.668 | INFO     | __main__:main:88 - Пользователь ввёл данные length = 5.0
2025-07-14 17:25:03.643 | INFO     | __main__:main:90 - Пользователь ввёл данные width = 6.0
2025-07-14 17:25:04.840 | INFO     | __main__:main:92 - Пользователь ввёл данные height = 3.0
2025-07-14 17:25:04.842 | SUCCESS  | __main__:calculate_wall_area:27 - Площадь стен посчитана
2025-07-14 17:25:04.842 | SUCCESS  | __main__:calculate_ceiling_area:31 - Площадь потолка посчитана
2025-07-14 17:25:04.842 | SUCCESS  | __main__:calculate_floor_area:35 - Площадь пола посчитана
2025-07-14 17:25:04.842 | SUCCESS  | __main__:add_room:58 - Комната добавлена
2025-07-14 17:25:07.430 | INFO     | __main__:main:101 - Пользователь ввёл данные wall_cost = 50.0
2025-07-14 17:25:08.379 | INFO     | __main__:main:105 - Пользователь ввёл данные ceiling_cost = 100.0
2025-07-14 17:25:10.519 | INFO     | __main__:main:107 - Пользователь ввёл данные floor_cost = 60.0
2025-07-14 17:25:10.519 | SUCCESS  | __main__:calculate_total_cost:68 - Результат посчитан total_cost = 6450.0
2025-07-14 17:25:10.520 | INFO     | __main__:main:112 - Открыт файл results.csv
2025-07-14 17:25:10.520 | SUCCESS  | __main__:calculate_wall_area:27 - Площадь стен посчитана
2025-07-14 17:25:10.520 | SUCCESS  | __main__:calculate_ceiling_area:31 - Площадь потолка посчитана
2025-07-14 17:25:10.520 | SUCCESS  | __main__:calculate_floor_area:35 - Площадь пола посчитана
2025-07-14 17:25:10.520 | SUCCESS  | __main__:<module>:147 - Расчёт стоимости окончен. Программа завершена.
